Workbook

Sheet Books
A1: Title | B1: Category | C1: Price (GBP) | D1: Rating (1-5) | E1: In stock | F1: Stock count | G1: UPC | H1: Reviews | I1: Product URL | J1: Image URL | K1: Description
A2: Logan Kade (Fallen Crest High #5.5) | B2: Academic | C2: 13.12 | D2: 2 | E2: Yes | F2: 5 | G2: 7093cf549cd2e7de | H2: 0 | I2: https://books.toscrape.com/catalogue/logan-kade-fallen-crest-high-55_384/index.html | J2: https://books.toscrape.com/media/cache/d9/4e/d94e6206c2decd3acd9a61b2cbac7eaf.jpg | K2: People think that just because they know my name, my reputation, and my family that they know me. They don't.They say I’m a manwhore, but who wouldn’t be with my face and body? They say I’m a partier, and that's not going to change. They say I'm a fighter, and hell yes I am. F*ck with mine, and I’ll f*ck you back ten times worse.So, yes. Maybe what they say is true, but th People think that just because they know my name, my reputation, and my family that they know me. They don't.They say I’m a manwhore, but who wouldn’t be with my face and body? They say I’m a partier, and that's not going to change. They say I'm a fighter, and hell yes I am. F*ck with mine, and I’ll f*ck you back ten times worse.So, yes. Maybe what they say is true, but that’s not all of me.I'm loyal to a damned fault. If you earn it, I'll never leave your side. And when I love, I love hard, but there's another side to me where it's dark and painful. That side's been kept hidden, until her. Taylor saw inside of me, and the second she was there, she owned me.People think they know me……but only she can see me. ...more
A3: #GIRLBOSS | B3: Add a comment | C3: 50.96 | D3: 1 | E3: Yes | F3: 3 | G3: 165affa7adb5eded | H3: 0 | I3: https://books.toscrape.com/catalogue/girlboss_113/index.html | J3: https://books.toscrape.com/media/cache/70/9a/709a7625e50abf3fc3f26c0396a62131.jpg | K3: The founder of Nasty Gal offers a sassy and irreverent manifesto for ambitious young women At seventeen, Sophia Amoruso decided to forgo continuing education to pursue a life of hitchhiking, dumpster diving, and petty thievery. Now, at twenty-nine, she is the Founder, CEO, and Creative Director of Nasty Gal, a $100+ million e-tailer that draws A-list publicity and rabid fa The founder of Nasty Gal offers a sassy and irreverent manifesto for ambitious young women At seventeen, Sophia Amoruso decided to forgo continuing education to pursue a life of hitchhiking, dumpster diving, and petty thievery. Now, at twenty-nine, she is the Founder, CEO, and Creative Director of Nasty Gal, a $100+ million e-tailer that draws A-list publicity and rabid fans for its leading-edge fashion and provocative online persona. Her story is extraordinary—and only part of the appeal of #GIRLBOSS. This aspirational book doesn’t patronize young women the way many business experts do. Amoruso shows readers how to channel their passion and hard work, while keeping their insecurities from getting in the way. She offers straight talk about making your voice heard and doing meaningful work. She’s proof that you can be a huge success without giving up your spirit of adventure or distinctive style. As she writes, "I have three pieces of advice I want you to remember: Don’t ever grow up. Don’t become a bore. Don’t let The Man get to you. OK? Cool. Then let’s do this.” ...more
A4: 23 Degrees South: A Tropical Tale of Changing Whether... | B4: Add a comment | C4: 35.79 | D4: 2 | E4: Yes | F4: 9 | G4: 61cf7eb9d2cd8bb0 | H4: 0 | I4: https://books.toscrape.com/catalogue/23-degrees-south-a-tropical-tale-of-changing-whether_556/index.html | J4: https://books.toscrape.com/media/cache/29/3e/293e31894cd2c5bf2aff452b8c818b66.jpg | K4: "Consistently entertaining courtesy of Rabin's humor-laced prose...a witty, boisterous ride!" -Kirkus Reviews"An action packed story complete with some hilarious scenes can be enjoyed in this amusing and entertaining adventurous adult coming-of-age tale...An exemplary and highly entertaining read for today’s hectic pace of living—highly recommended." --Chanticleer Reviews2 "Consistently entertaining courtesy of Rabin's humor-laced prose...a witty, boisterous ride!" -Kirkus Reviews"An action packed story complete with some hilarious scenes can be enjoyed in this amusing and entertaining adventurous adult coming-of-age tale...An exemplary and highly entertaining read for today’s hectic pace of living—highly recommended." --Chanticleer Reviews23 DEGREES SOUTH follows two 23 year-old childhood pals, Hart and Simon, on a twisting and unexpected adventure of force-fed self-discovery. The story departs from the tennis courts of Southern California traveling to the back streets of Sao Paulo, through the treacherous jungles of Brazil, then back again. Meet an eclectic collection of characters, including a Capoeira Master, a Jesuit Priest, and a geriatric Nazi, who all weave their way in, out, and around the path of our two heroes. ...more
A5: A Brush of Wings (Angels Walking #3) | B5: Add a comment | C5: 55.51 | D5: 1 | E5: Yes | F5: 14 | G5: 01a177623cce9596 | H5: 0 | I5: https://books.toscrape.com/catalogue/a-brush-of-wings-angels-walking-3_651/index.html | J5: https://books.toscrape.com/media/cache/4d/16/4d163d43cb4aa624e599330a39abace5.jpg | K5: From #1 New York Times bestselling author Karen Kingsbury comes the third novel in the unforgettable Angels Walking series about divine intervention and the trials and triumphs of life for a group of friends.Despite needing a heart transplant and against the advice of her doctor, Mary Catherine moves to Uganda to work at a brand new orphanage. Whatever time she has left, M From #1 New York Times bestselling author Karen Kingsbury comes the third novel in the unforgettable Angels Walking series about divine intervention and the trials and triumphs of life for a group of friends.Despite needing a heart transplant and against the advice of her doctor, Mary Catherine moves to Uganda to work at a brand new orphanage. Whatever time she has left, Mary Catherine wants to spend it helping children—especially since there will be no children of her own. The only problem is Major League Baseball player Marcus Dillinger, the man she never meant to fall in love with. Neither Marcus nor Mary Catherine’s other friends—Tyler Ames and Sami Dawson—know just how serious her heart condition is.Still, Marcus is sure in the depths of his soul that something isn’t right. Ultimately his correspondence with Mary Catherine leads him on a desperate life-or-death mission to rescue her and get her to a US hospital before time runs out. Meanwhile, Sami and Tyler struggle with issues of their own. In a season when Tyler plans to ask Sami to marry him, the very core of their relationship is in jeopardy.The team of angels walking is busier than ever in this epic battle between life and death. A Brush of Wings is a poignant tale of love, sacrifice, and the power of faith. ...more
A6: A Clash of Kings (A Song of Ice and Fire #2) | B6: Add a comment | C6: 10.79 | D6: 3 | E6: Yes | F6: 5 | G6: 89a89e76f3516357 | H6: 0 | I6: https://books.toscrape.com/catalogue/a-clash-of-kings-a-song-of-ice-and-fire-2_356/index.html | J6: https://books.toscrape.com/media/cache/1a/29/1a298a157f4113d6e0127521aaa1f5f0.jpg | K6: Alternate cover edition can be found here. Time is out of joint. The summer of peace and plenty, ten years long, is drawing to a close, and the harsh, chill winter approaches like an angry beast. Two great leaders—Lord Eddard Stark and Robert Baratheon—who held sway over an age of enforced peace are dead...victims of royal treachery. Now, from the ancient citadel of Dragon Alternate cover edition can be found here. Time is out of joint. The summer of peace and plenty, ten years long, is drawing to a close, and the harsh, chill winter approaches like an angry beast. Two great leaders—Lord Eddard Stark and Robert Baratheon—who held sway over an age of enforced peace are dead...victims of royal treachery. Now, from the ancient citadel of Dragonstone to the forbidding shores of Winterfell, chaos reigns, as pretenders to the Iron Throne of the Seven Kingdoms prepare to stake their claims through tempest, turmoil, and war. As a prophecy of doom cuts across the sky—a comet the color of blood and flame—six factions struggle for control of a divided land. Eddard's son Robb has declared himself King in the North. In the south, Joffrey, the heir apparent, rules in name only, victim of the scheming courtiers who teem over King's Landing. Robert's two brothers each seek their own dominion, while a disfavored house turns once more to conquest. And a continent away, an exiled queen, the Mother of Dragons, risks everything to lead her precious brood across a hard hot desert to win back the crown that is rightfully hers. A Clash of Kings transports us into a magnificent, forgotten land of revelry and revenge, wizardry and wartime. It is a tale in which maidens cavort with madmen, brother plots against brother, and the dead rise to walk in the night. Here a princess masquerades as an orphan boy; a knight of the mind prepares a poison for a treacherous sorceress; and wild men descend from the Mountains of the Moon to ravage the countryside. Against a backdrop of incest and fratricide, alchemy and murder, the price of glory may be measured in blood. And the spoils of victory may just go to the men and women possessed of the coldest steel...and the coldest hearts. For when rulers clash, all of the land feels the tremors. Audacious, inventive, brilliantly imagined, A Clash of Kings is a novel of dazzling beauty and boundless enchantment;a tale of pure excitement you will never forget. ...more
A7: A Game of Thrones (A Song of Ice and Fire #1) | B7: Add a comment | C7: 46.42 | D7: 2 | E7: Yes | F7: 5 | G7: 03cbb67c0f990d87 | H7: 0 | I7: https://books.toscrape.com/catalogue/a-game-of-thrones-a-song-of-ice-and-fire-1_358/index.html | J7: https://books.toscrape.com/media/cache/13/d1/13d11b26b46484ee73e9923ff307a7b4.jpg | K7: Summers span decades. Winter can last a lifetime. And the struggle for the Iron Throne has begun.As Warden of the north, Lord Eddard Stark counts it a curse when King Robert bestows on him the office of the Hand. His honour weighs him down at court where a true man does what he will, not what he must … and a dead enemy is a thing of beauty.The old gods have no power in the Summers span decades. Winter can last a lifetime. And the struggle for the Iron Throne has begun.As Warden of the north, Lord Eddard Stark counts it a curse when King Robert bestows on him the office of the Hand. His honour weighs him down at court where a true man does what he will, not what he must … and a dead enemy is a thing of beauty.The old gods have no power in the south, Stark’s family is split and there is treachery at court. Worse, the vengeance-mad heir of the deposed Dragon King has grown to maturity in exile in the Free Cities. He claims the Iron Throne. ...more
A8: A Hero's Curse (The Unseen Chronicles #1) | B8: Add a comment | C8: 50.49 | D8: 3 | E8: Yes | F8: 9 | G8: c181ca8eabe7d18c | H8: 0 | I8: https://books.toscrape.com/catalogue/a-heros-curse-the-unseen-chronicles-1_557/index.html | J8: https://books.toscrape.com/media/cache/95/68/95685fabe00befa6dc91277cde703b55.jpg | K8: Essie Brightsday has never heard a rock basilisk scream. She has never worn magical armor, stood up to a queen, or run from dragons. Instead, Essie, her sarcastic cat Tigrabum, (just call him "Tig"), and her secretive family struggle to survive on their small farm nestled against the forbidding cliffs of the Valley of Fire. But all that is about to change when a rebellion Essie Brightsday has never heard a rock basilisk scream. She has never worn magical armor, stood up to a queen, or run from dragons. Instead, Essie, her sarcastic cat Tigrabum, (just call him "Tig"), and her secretive family struggle to survive on their small farm nestled against the forbidding cliffs of the Valley of Fire. But all that is about to change when a rebellion against the cruel interim ruler is sparked. Forced to flee for their lives, Essie and Tig lose themselves in the twisting labyrinth of the ancient lava flow. When Essie finds proof that the missing King Mactogonii may be alive, she is given the opportunity to help restore stability to the kingdom. But the course of her journey will force her to face her deepest fears and unravel the mystery behind her own blindness...if Essie can survive the encounter. ...more
A9: A People's History of the United States | B9: Add a comment | C9: 40.79 | D9: 2 | E9: Yes | F9: 14 | G9: 1ad06aed9349af46 | H9: 0 | I9: https://books.toscrape.com/catalogue/a-peoples-history-of-the-united-states_654/index.html | J9: https://books.toscrape.com/media/cache/75/20/75200336c141156746000f7055df344a.jpg | K9: Known for its lively, clear prose as well as its scholarly research, A People's History of the United States is the only volume to tell America's story from the point of view of - and in the words of - America's women, factory workers, African Americans, Native Americans, working poor, and immigrant laborers.
A10: A Series of Catastrophes and Miracles: A True Story of Love, Science, and Cancer | B10: Add a comment | C10: 56.48 | D10: 2 | E10: Yes | F10: 14 | G10: c1379d3744f1dd2c | H10: 0 | I10: https://books.toscrape.com/catalogue/a-series-of-catastrophes-and-miracles-a-true-story-of-love-science-and-cancer_655/index.html | J10: https://books.toscrape.com/media/cache/9b/20/9b2076ce7414103a093ce2459d089969.jpg | K10: A wry, witty account of what it is like to face death—and be restored to life.After being diagnosed in her early 40s with metastatic melanoma—a "rapidly fatal" form of cancer—journalist and mother of two Mary Elizabeth Williams finds herself in a race against the clock. She takes a once-in-a-lifetime chance and joins a clinical trial for immunotherapy, a revolutionary drug A wry, witty account of what it is like to face death—and be restored to life.After being diagnosed in her early 40s with metastatic melanoma—a "rapidly fatal" form of cancer—journalist and mother of two Mary Elizabeth Williams finds herself in a race against the clock. She takes a once-in-a-lifetime chance and joins a clinical trial for immunotherapy, a revolutionary drug regimen that trains the body to vanquish malignant cells. Astonishingly, her cancer disappears entirely in just a few weeks. But at the same time, her best friend embarks on a cancer journey of her own—with very different results. Williams's experiences as a patient and a medical test subject reveal with stark honesty what it takes to weather disease, the extraordinary new developments that are rewriting the rules of science—and the healing power of human connection. ...more
A11: Angels Walking (Angels Walking #1) | B11: Add a comment | C11: 34.2 | D11: 2 | E11: Yes | F11: 14 | G11: 1fbb5f786e53a0ce | H11: 0 | I11: https://books.toscrape.com/catalogue/angels-walking-angels-walking-1_662/index.html | J11: https://books.toscrape.com/media/cache/50/0e/500eeb810e940424827580574e46852c.jpg | K11: When former national baseball star Tyler Ames suffers a career-ending injury, all he can think about is putting his life back together the way it was before. He has lost everyone he loves on his way to the big leagues. Then just when things seem to be turning around, Tyler hits rock bottom. Across the country, Tyler’s one true love Sami Dawson has moved on. A series of sma When former national baseball star Tyler Ames suffers a career-ending injury, all he can think about is putting his life back together the way it was before. He has lost everyone he loves on his way to the big leagues. Then just when things seem to be turning around, Tyler hits rock bottom. Across the country, Tyler’s one true love Sami Dawson has moved on. A series of small miracles leads Tyler to a maintenance job at a retirement home and a friendship with Virginia Hutcheson, an old woman with Alzheimer’s who strangely might have the answers he so desperately seeks.A team of Angels Walking take on the mission to restore hope for Tyler, Sami, and Virginia. Can such small and seemingly insignificant actions of the unseen bring healing and redemption? And can the words of a stranger rekindle lost love? Every journey begins with a step.It is time for the mission to begin… ...more
A12: Cell | B12: Add a comment | C12: 20.29 | D12: 4 | E12: Yes | F12: 14 | G12: bfbb54bc8cdeed2b | H12: 0 | I12: https://books.toscrape.com/catalogue/cell_674/index.html | J12: https://books.toscrape.com/media/cache/0b/97/0b97282ed82b771ed328e05386a84adb.jpg | K12: Witness Stephen King's triumphant, blood-spattered return to the genre that made him famous. Cell, the king of horror's homage to zombie films (the book is dedicated in part to George A. Romero) is his goriest, most horrific novel in years, not to mention the most intensely paced. Casting aside his love of elaborate character and town histories and penchant for delayed gra Witness Stephen King's triumphant, blood-spattered return to the genre that made him famous. Cell, the king of horror's homage to zombie films (the book is dedicated in part to George A. Romero) is his goriest, most horrific novel in years, not to mention the most intensely paced. Casting aside his love of elaborate character and town histories and penchant for delayed gratification, King yanks readers off their feet within the first few pages; dragging them into the fray and offering no chance catch their breath until the very last page. In Cell King taps into readers fears of technological warfare and terrorism. Mobile phones deliver the apocalypse to millions of unsuspecting humans by wiping their brains of any humanity, leaving only aggressive and destructive impulses behind. Those without cell phones, like illustrator Clayton Riddell and his small band of "normies," must fight for survival, and their journey to find Clayton's estranged wife and young son rockets the book toward resolution. Fans that have followed King from the beginning will recognize and appreciate Cell as a departure--King's writing has not been so pure of heart and free of hang-ups in years (wrapping up his phenomenal Dark Tower series and receiving a medal from the National Book Foundation doesn't hurt either). "Retirement" clearly suits King, and lucky for us, having nothing left to prove frees him up to write frenzied, juiced-up horror-thrillers like Cell. Stay tuned for more from the hardest-working retiree in the business with Lisey's Story, coming in October 2006. --Daphne Durham ...more
A13: Code Name Verity (Code Name Verity #1) | B13: Add a comment | C13: 22.13 | D13: 4 | E13: Yes | F13: 14 | G13: 33a3e0e3ffde0dcd | H13: 0 | I13: https://books.toscrape.com/catalogue/code-name-verity-code-name-verity-1_680/index.html | J13: https://books.toscrape.com/media/cache/f5/58/f55886d1bf600529a35e1bd932c78ca0.jpg | K13: I have two weeks. You'll shoot me at the end no matter what I do.That's what you do to enemy agents. It's what we do to enemy agents. But I look at all the dark and twisted roads ahead and cooperation is the easy way out. Possibly the only way out for a girl caught red-handed doing dirty work like mine - and I will do anything, anything to avoid SS-Hauptsturmführer von Lin I have two weeks. You'll shoot me at the end no matter what I do.That's what you do to enemy agents. It's what we do to enemy agents. But I look at all the dark and twisted roads ahead and cooperation is the easy way out. Possibly the only way out for a girl caught red-handed doing dirty work like mine - and I will do anything, anything to avoid SS-Hauptsturmführer von Linden interrogating me again.He has said that I can have as much paper as I need. All I have to do is cough up everything I can remember about the British War Effort. And I'm going to. But the story of how I came to be here starts with my friend Maddie. She is the pilot who flew me into France - an Allied Invasion of Two.We are a sensational team. ...more
... A142: Shadows of the Past (Logan Point #1) | B142: Christian Fiction | C142: 39.67 | D142: 5 | E142: Yes | F142: 8 | G142: bee6e93e9976f4fa | H142: 0 | I142: https://books.toscrape.com/catalogue/shadows-of-the-past-logan-point-1_541/index.html | J142: https://books.toscrape.com/media/cache/93/e0/93e0ec623673a8f83598c9aa7b6c94ec.jpg | K142: Psychology professor and criminal profiler Taylor Martin prides herself on being able to solve any crime, except the one she wants most desperately to solve--the disappearance of her father twenty years ago. When she finally has a lead on his whereabouts, Taylor returns home to Logan Point, Mississippi, to investigate. But as she is stalking the truth about the past, someo Psychology professor and criminal profiler Taylor Martin prides herself on being able to solve any crime, except the one she wants most desperately to solve--the disappearance of her father twenty years ago. When she finally has a lead on his whereabouts, Taylor returns home to Logan Point, Mississippi, to investigate. But as she is stalking the truth about the past, someone is stalking her.Nick Sinclair pens mystery novels for a living, but the biggest mystery to him is how he can ever get over the death of his wife--a tragedy he believes he could have prevented. With his estranged brother the only family he has left, Nick sets out to find him. But when he crosses paths with Taylor, all he seems to find is trouble. ...more
A143: Alice in Wonderland (Alice's Adventures in Wonderland #1) | B143: Classics | C143: 55.53 | D143: 1 | E143: Yes | F143: 1 | G143: cd2a2a70dd5d176d | H143: 0 | I143: https://books.toscrape.com/catalogue/alice-in-wonderland-alices-adventures-in-wonderland-1_5/index.html | J143: https://books.toscrape.com/media/cache/96/ee/96ee77d71a31b7694dac6855f6affe4e.jpg
A144: And Then There Were None | B144: Classics | C144: 35.01 | D144: 2 | E144: Yes | F144: 3 | G144: cfe350b20d23b02b | H144: 0 | I144: https://books.toscrape.com/catalogue/and-then-there-were-none_119/index.html | J144: https://books.toscrape.com/media/cache/21/bf/21bf2eb0bff3134837def8bd40845ba0.jpg | K144: First, there were ten - a curious assortment of strangers summoned as weekend guests to a private island off the coast of Devon. Their host, an eccentric millionaire unknown to all of them, is nowhere to be found. All that the guests have in common is a wicked past they're unwilling to reveal - and a secret that will seal their fate. For each has been marked for murder. On First, there were ten - a curious assortment of strangers summoned as weekend guests to a private island off the coast of Devon. Their host, an eccentric millionaire unknown to all of them, is nowhere to be found. All that the guests have in common is a wicked past they're unwilling to reveal - and a secret that will seal their fate. For each has been marked for murder. One by one they fall prey. Before the weekend is out, there will be none. And only the dead are above suspicion. ...more
A145: Animal Farm | B145: Classics | C145: 57.22 | D145: 3 | E145: Yes | F145: 4 | G145: 1451b55e5e56bb89 | H145: 0 | I145: https://books.toscrape.com/catalogue/animal-farm_313/index.html | J145: https://books.toscrape.com/media/cache/10/db/10db56354b4550d92270c6f097d9bebc.jpg | K145: Tired of their servitude to man, a group of farm animals revolt and establish their own society, only to be betrayed into worse servitude by their leaders, the pigs, whose slogan becomes: "All animals are equal, but some animals are more equal than others." This 1945 satire addresses the socialist/communist philosophy of Stalin in the Soviet Union.
A146: Beowulf | B146: Classics | C146: 38.35 | D146: 2 | E146: Yes | F146: 3 | G146: 3fb69f34e178d494 | H146: 0 | I146: https://books.toscrape.com/catalogue/beowulf_126/index.html | J146: https://books.toscrape.com/media/cache/dd/6e/dd6e7b84e99f3b4b5655ea0db74af2b4.jpg | K146: The national bestseller and winner of the Whitbread Award. Composed toward the end of the first millennium, Beowulf is the classic Northern epic of a hero’s triumphs as a young warrior and his fated death as a defender of his people. The poem is about encountering the monstrous, defeating it, and then having to live on, physically and psychically exposed in the exhausted a The national bestseller and winner of the Whitbread Award. Composed toward the end of the first millennium, Beowulf is the classic Northern epic of a hero’s triumphs as a young warrior and his fated death as a defender of his people. The poem is about encountering the monstrous, defeating it, and then having to live on, physically and psychically exposed in the exhausted aftermath. It is not hard to draw parallels in this story to the historical curve of consciousness in the twentieth century, but the poem also transcends such considerations, telling us psychological and spiritual truths that are permanent and liberating.Beowulf is considered to have been composed between the 8th and the early 11th century. According to Wikipedia, it was first PUBLISHED in 1814 in a version by John Josias Conybeare. ...more
A147: Candide | B147: Classics | C147: 58.63 | D147: 3 | E147: Yes | F147: 4 | G147: 2798974abc8a58a8 | H147: 0 | I147: https://books.toscrape.com/catalogue/candide_316/index.html | J147: https://books.toscrape.com/media/cache/e3/c4/e3c4aba2409bb769a6488805e3fc4709.jpg | K147: Brought up in the household of a powerful Baron, Candide is an open-minded young man, whose tutor, Pangloss, has instilled in him the belief that 'all is for the best'. But when his love for the Baron's rosy-cheeked daughter is discovered, Candide is cast out to make his own way in the world. And so he and his various companions begin a breathless tour of Europe, South Ame Brought up in the household of a powerful Baron, Candide is an open-minded young man, whose tutor, Pangloss, has instilled in him the belief that 'all is for the best'. But when his love for the Baron's rosy-cheeked daughter is discovered, Candide is cast out to make his own way in the world. And so he and his various companions begin a breathless tour of Europe, South America and Asia, as an outrageous series of disasters befall them - earthquakes, syphilis, a brush with the Inquisition, murder - sorely testing the young hero's optimism. ...more
A148: Emma | B148: Classics | C148: 32.93 | D148: 2 | E148: Yes | F148: 1 | G148: 2e69730561ed70ad | H148: 0 | I148: https://books.toscrape.com/catalogue/emma_17/index.html | J148: https://books.toscrape.com/media/cache/09/63/09638baaef52f03827c215029c632a13.jpg | K148: 'I never have been in love; it is not my way, or my nature; and I do not think I ever shall.'Beautiful, clever, rich - and single - Emma Woodhouse is perfectly content with her life and sees no need for either love or marriage. Nothing, however, delights her more than interfering in the romantic lives of others. But when she ignores the warnings of her good friend Mr. Knig 'I never have been in love; it is not my way, or my nature; and I do not think I ever shall.'Beautiful, clever, rich - and single - Emma Woodhouse is perfectly content with her life and sees no need for either love or marriage. Nothing, however, delights her more than interfering in the romantic lives of others. But when she ignores the warnings of her good friend Mr. Knightley and attempts to arrange a suitable match for her protegee Harriet Smith, her carefully laid plans soon unravel and have consequences that she never expected. With its imperfect but charming heroine and its witty and subtle exploration of relationships, Emma is often seen as Jane Austen's most flawless work.This edition includes a new chronology and additional suggestions for further reading. ...more
A149: Gone with the Wind | B149: Classics | C149: 32.49 | D149: 3 | E149: Yes | F149: 4 | G149: 23310ce84d3c9f85 | H149: 0 | I149: https://books.toscrape.com/catalogue/gone-with-the-wind_324/index.html | J149: https://books.toscrape.com/media/cache/27/82/2782701b5c877cb063065b9fc14c5b13.jpg | K149: Margaret Mitchell's epic novel of love and war won the Pulitzer Prize and one of the most popular and celebrated movies of all time. Many novels have been written about the Civil War and its aftermath. None take us into the burning fields and cities of the American South as Gone With the Wind does, creating haunting scenes and thrilling portraits of characters so vivid tha Margaret Mitchell's epic novel of love and war won the Pulitzer Prize and one of the most popular and celebrated movies of all time. Many novels have been written about the Civil War and its aftermath. None take us into the burning fields and cities of the American South as Gone With the Wind does, creating haunting scenes and thrilling portraits of characters so vivid that we remember their words and feel their fear and hunger for the rest of our lives. In the two main characters, the white-shouldered, irresistible Scarlett and the flashy, contemptuous Rhett, Margaret Mitchell not only conveyed a timeless story of survival under the harshest of circumstances, she also created two of the most famous lovers in the English-speaking world since Romeo and Juliet. ...more
A150: Little Women (Little Women #1) | B150: Classics | C150: 28.07 | D150: 4 | E150: Yes | F150: 4 | G150: deda806b68b0aa11 | H150: 0 | I150: https://books.toscrape.com/catalogue/little-women-little-women-1_331/index.html | J150: https://books.toscrape.com/media/cache/81/f5/81f559ebe403317226fa8b611e35ce8a.jpg | K150: Little Women is the heartwarming story of the March family that has thrilled generations of readers. It is the story of four sisters--Jo, Meg, Amy and Beth-- and of the courage, humor and ingenuity they display to survive poverty and the absence of their father during the Civil War.
A151: Of Mice and Men | B151: Classics | C151: 47.11 | D151: 2 | E151: Yes | F151: 1 | G151: 39592d9d72e717c4 | H151: 0 | I151: https://books.toscrape.com/catalogue/of-mice-and-men_37/index.html | J151: https://books.toscrape.com/media/cache/0f/ca/0fca4597765ffacdb7bd529fc5eb88fa.jpg | K151: The compelling story of two outsiders striving to find their place in an unforgiving world. Drifters in search of work, George and his simple-minded friend Lennie have nothing in the world except each other and a dream--a dream that one day they will have some land of their own. Eventually they find work on a ranch in California’s Salinas Valley, but their hopes are doomed The compelling story of two outsiders striving to find their place in an unforgiving world. Drifters in search of work, George and his simple-minded friend Lennie have nothing in the world except each other and a dream--a dream that one day they will have some land of their own. Eventually they find work on a ranch in California’s Salinas Valley, but their hopes are doomed as Lennie, struggling against extreme cruelty, misunderstanding and feelings of jealousy, becomes a victim of his own strength. Tackling universal themes such as the friendship of a shared vision, and giving voice to America’s lonely and dispossessed, Of Mice and Men has proved one of Steinbeck’s most popular works, achieving success as a novel, a Broadway play and three acclaimed films. ...more
A152: Sense and Sensibility | B152: Classics | C152: 37.46 | D152: 1 | E152: Yes | F152: 1 | G152: 35e44170702139a4 | H152: 0 | I152: https://books.toscrape.com/catalogue/sense-and-sensibility_49/index.html | J152: https://books.toscrape.com/media/cache/7d/53/7d53e2264b9647ee307259be9f73585d.jpg | K152: 'The more I know of the world, the more am I convinced that I shall never see a man whom I can really love. I require so much!'Marianne Dashwood wears her heart on her sleeve, and when she falls in love with the dashing but unsuitable John Willoughby she ignores her sister Elinor's warning that her impulsive behaviour leaves her open to gossip and innuendo. Meanwhile Elino 'The more I know of the world, the more am I convinced that I shall never see a man whom I can really love. I require so much!'Marianne Dashwood wears her heart on her sleeve, and when she falls in love with the dashing but unsuitable John Willoughby she ignores her sister Elinor's warning that her impulsive behaviour leaves her open to gossip and innuendo. Meanwhile Elinor, always sensitive to social convention, is struggling to conceal her own romantic disappointment, even from those closest to her. Through their parallel experience of love—and its threatened loss—the sisters learn that sense must mix with sensibility if they are to find personal happiness in a society where status and money govern the rules of love.This edition includes explanatory notes, textual variants between the first and second editions, and Tony Tanner's introduction to the original Penguin Classic edition. ...more
A153: The Complete Stories and Poems (The Works of Edgar Allan Poe [Cameo Edition]) | B153: Classics | C153: 26.78 | D153: 4 | E153: Yes | F153: 3 | G153: cad70d6ffd53912f | H153: 0 | I153: https://books.toscrape.com/catalogue/the-complete-stories-and-poems-the-works-of-edgar-allan-poe-cameo-edition_238/index.html | J153: https://books.toscrape.com/media/cache/42/c4/42c48f11b7e70a0f76c5ba9cb5c5018a.jpg | K153: This single volume brings together all of Poe's stories and poems, and illuminates the diverse and multifaceted genius of one of the greatest and most influential figures in American literary history.
A154: The Hound of the Baskervilles (Sherlock Holmes #5) | B154: Classics | C154: 14.82 | D154: 2 | E154: Yes | F154: 4 | G154: 6587f46697fc4443 | H154: 0 | I154: https://books.toscrape.com/catalogue/the-hound-of-the-baskervilles-sherlock-holmes-5_348/index.html | J154: https://books.toscrape.com/media/cache/1f/b0/1fb03cdabe6001c8a2620f65e025cbd5.jpg | K154: Holmes and Watson are faced with their most terrifying case yet. The legend of the devil-beast that haunts the moors around the Baskerville family's home warns the descendants of that ancient clan never to venture out in those dark hours when the power of evil is exalted. Now, the most recent Baskerville, Sir Charles, is dead and the footprints of a giant hound have been f Holmes and Watson are faced with their most terrifying case yet. The legend of the devil-beast that haunts the moors around the Baskerville family's home warns the descendants of that ancient clan never to venture out in those dark hours when the power of evil is exalted. Now, the most recent Baskerville, Sir Charles, is dead and the footprints of a giant hound have been found near his body. Will the new heir meet the same fate? ...more
A155: The Little Prince | B155: Classics | C155: 45.42 | D155: 2 | E155: Yes | F155: 1 | G155: 1aeca7d078d57deb | H155: 0 | I155: https://books.toscrape.com/catalogue/the-little-prince_72/index.html | J155: https://books.toscrape.com/media/cache/c0/78/c078355608dd81c7c5e4f5e1c5f73d23.jpg | K155: Moral allegory and spiritual autobiography, The Little Prince is the most translated book in the French language. With a timeless charm it tells the story of a little boy who leaves the safety of his own tiny planet to travel the universe, learning the vagaries of adult behaviour through a series of extraordinary encounters. His personal odyssey culminates in a voyage to E Moral allegory and spiritual autobiography, The Little Prince is the most translated book in the French language. With a timeless charm it tells the story of a little boy who leaves the safety of his own tiny planet to travel the universe, learning the vagaries of adult behaviour through a series of extraordinary encounters. His personal odyssey culminates in a voyage to Earth and further adventures. ...more
... A265: The Boys in the Boat: Nine Americans and Their Epic Quest for Gold at the 1936 Berlin Olympics | B265: Default | C265: 22.6 | D265: 4 | E265: Yes | F265: 19 | G265: e10e1e165dc8be4a | H265: 0 | I265: https://books.toscrape.com/catalogue/the-boys-in-the-boat-nine-americans-and-their-epic-quest-for-gold-at-the-1936-berlin-olympics_992/index.html | J265: https://books.toscrape.com/media/cache/66/88/66883b91f6804b2323c8369331cb7dd1.jpg | K265: For readers of Laura Hillenbrand's Seabiscuit and Unbroken, the dramatic story of the American rowing team that stunned the world at Hitler's 1936 Berlin Olympics Daniel James Brown’s robust book tells the story of the University of Washington’s 1936 eight-oar crew and their epic quest for an Olympic gold medal, a team that transformed the sport and grabbed the attention o For readers of Laura Hillenbrand's Seabiscuit and Unbroken, the dramatic story of the American rowing team that stunned the world at Hitler's 1936 Berlin Olympics Daniel James Brown’s robust book tells the story of the University of Washington’s 1936 eight-oar crew and their epic quest for an Olympic gold medal, a team that transformed the sport and grabbed the attention of millions of Americans. The sons of loggers, shipyard workers, and farmers, the boys defeated elite rivals first from eastern and British universities and finally the German crew rowing for Adolf Hitler in the Olympic games in Berlin, 1936. The emotional heart of the story lies with one rower, Joe Rantz, a teenager without family or prospects, who rows not for glory, but to regain his shattered self-regard and to find a place he can call home. The crew is assembled by an enigmatic coach and mentored by a visionary, eccentric British boat builder, but it is their trust in each other that makes them a victorious team. They remind the country of what can be done when everyone quite literally pulls together—a perfect melding of commitment, determination, and optimism. Drawing on the boys’ own diaries and journals, their photos and memories of a once-in-a-lifetime shared dream, The Boys in the Boat is an irresistible story about beating the odds and finding hope in the most desperate of times—the improbable, intimate story of nine working-class boys from the American west who, in the depths of the Great Depression, showed the world what true grit really meant. It will appeal to readers of Erik Larson, Timothy Egan, James Bradley, and David Halberstam's The Amateurs. ...more
A266: The Bridge to Consciousness: I'm Writing the Bridge Between Science and Our Old and New Beliefs. | B266: Default | C266: 32 | D266: 3 | E266: Yes | F266: 15 | G266: efc3768127714ec3 | H266: 0 | I266: https://books.toscrape.com/catalogue/the-bridge-to-consciousness-im-writing-the-bridge-between-science-and-our-old-and-new-beliefs_840/index.html | J266: https://books.toscrape.com/media/cache/fe/b7/feb764b2afa54991cfdbbffdf501b333.jpg
A267: The Coming Woman: A Novel Based on the Life of the Infamous Feminist, Victoria Woodhull | B267: Default | C267: 17.93 | D267: 3 | E267: Yes | F267: 19 | G267: e72a5dfc7e9267b2 | H267: 0 | I267: https://books.toscrape.com/catalogue/the-coming-woman-a-novel-based-on-the-life-of-the-infamous-feminist-victoria-woodhull_993/index.html | J267: https://books.toscrape.com/media/cache/3d/54/3d54940e57e662c4dd1f3ff00c78cc64.jpg | K267: "If you have a heart, if you have a soul, Karen Hicks' The Coming Woman will make you fall in love with Victoria Woodhull."-Kinky Friedman, author and Governor of the Heart of Texas "What kind of confidence would it take for a woman to buck the old boy's club of politics in 1872? More than 140 years pre-Hillary, there was Victoria Woodhull. This book takes you back with a "If you have a heart, if you have a soul, Karen Hicks' The Coming Woman will make you fall in love with Victoria Woodhull."-Kinky Friedman, author and Governor of the Heart of Texas "What kind of confidence would it take for a woman to buck the old boy's club of politics in 1872? More than 140 years pre-Hillary, there was Victoria Woodhull. This book takes you back with a breathtaking, present-tense bird's eye view into a time when women's liberation was primarily confined to one woman's very capable, independent mind. I couldn't put it down."---Ruth Buzzi, Golden Globe Award winner and Television Hall of Fame inductee"Sadly, too many Americans have never heard of Victoria Woodhull, let alone learned of her story: her revolutionary campaign for the presidency at a time when women weren't even allowed to vote, her support for worker's rights, or her feminist commitment to equality, a century before the official battle over the Equal Rights Amendment. But in The Coming Woman, Karen Hicks brings Woodhull's efforts to life, and reminds us that some of our nation's greatest figures aren't always featured in the history books. It is a riveting account of an amazing woman and her struggle for justice and human dignity, told in an engaging and eminently readable style."-Tim Wise, author, "White Like Me: Reflections on Race from a Privileged Son""The Coming Woman" is a novel based on the life of feminist Victoria Woodhull, the first woman to run for U.S. President, 50 years before women could even vote!Running for President wasn't Victoria's only first as a woman. She was also the first to own a successful Wall Street firm, the first to publish a successful national newspaper, and the first to head the two-million-member Spiritualist Association. She was the first woman to enter the Senate Judiciary Committee chambers to petition for woman's suffrage, her argument changing the entire focus of the suffragist movement by pointing out that the 14th and 15th Amendments already gave women the vote.In her campaign for the Presidency, Victoria Woodhull boldly addressed many of the issues we still face today: equal pay for equal work; freedom in love; corporate greed and political corruption fueled by powerful lobbyists; and the increasing disparity between the rich and the poor, to name only a few. Her outspoken and common-sense ideas may shed a new perspective on the parallel conundrums of today's world.This bold, beautiful, and sexually progressive woman dared to take on society and religion. To make an example of the hypocrisy in what Mark Twain dubbed The Gilded Age, she exposed the extramarital affairs of the most popular religious figure of the day (Henry Ward Beecher). This led to her persecution and imprisonment and the longest, most infamous trial of the 19th century. But it did not stop her fight for equality.Victoria's epic story, set in the late 1800s, comes to life in a modern, fictional style, while staying true to the actual words and views of the many well-known characters. ...more
A268: The Demon-Haunted World: Science as a Candle in the Dark | B268: Default | C268: 52.25 | D268: 4 | E268: Yes | F268: 3 | G268: f51062bf579507d9 | H268: 0 | I268: https://books.toscrape.com/catalogue/the-demon-haunted-world-science-as-a-candle-in-the-dark_242/index.html | J268: https://books.toscrape.com/media/cache/4a/35/4a352dc298e4bbe6ba5f81bbc0d41ca0.jpg | K268: How can we make intelligent decisions about our increasingly technology-driven lives if we don't understand the difference between the myths of pseudoscience and the testable hypotheses of science? Pulitzer Prize-winning author and distinguished astronomer Carl Sagan argues that scientific thinking is critical not only to the pursuit of truth but to the very well-being of How can we make intelligent decisions about our increasingly technology-driven lives if we don't understand the difference between the myths of pseudoscience and the testable hypotheses of science? Pulitzer Prize-winning author and distinguished astronomer Carl Sagan argues that scientific thinking is critical not only to the pursuit of truth but to the very well-being of our democratic institutions.Casting a wide net through history and culture, Sagan examines and authoritatively debunks such celebrated fallacies of the past as witchcraft, faith healing, demons, and UFOs. And yet, disturbingly, in today's so-called information age, pseudoscience is burgeoning with stories of alien abduction, channeling past lives, and communal hallucinations commanding growing attention and respect. As Sagan demonstrates with lucid eloquence, the siren song of unreason is not just a cultural wrong turn but a dangerous plunge into darkness that threatens our most basic freedoms. ...more
A269: The Dream Thieves (The Raven Cycle #2) | B269: Default | C269: 34.5 | D269: 1 | E269: Yes | F269: 5 | G269: fec06f52054ea900 | H269: 0 | I269: https://books.toscrape.com/catalogue/the-dream-thieves-the-raven-cycle-2_400/index.html | J269: https://books.toscrape.com/media/cache/d9/7a/d97a3a4a65b5275ab506b28c7a88e0a5.jpg | K269: If you could steal things from dreams, what would you take?Ronan Lynch has secrets. Some he keeps from others. Some he keeps from himself.One secret: Ronan can bring things out of his dreams.And sometimes he's not the only one who wants those things.Ronan is one of the raven boys—a group of friends, practically brothers, searching for a dead king named Glendower, who they If you could steal things from dreams, what would you take?Ronan Lynch has secrets. Some he keeps from others. Some he keeps from himself.One secret: Ronan can bring things out of his dreams.And sometimes he's not the only one who wants those things.Ronan is one of the raven boys—a group of friends, practically brothers, searching for a dead king named Glendower, who they think is hidden somewhere in the hills by their elite private school, Aglionby Academy. The path to Glendower has long lived as an undercurrent beneath town. But now, like Ronan's secrets, it is beginning to rise to the surface—changing everything in its wake.Of The Raven Boys, Entertainment Weekly wrote, "Maggie Stiefvater's can't-put-it-down paranormal adventure will leave you clamoring for book two." Now the second book is here, with the same wild imagination, dark romance, and heart-stopping twists that only Maggie Stiefvater can conjure. ...more
A270: The Emerald Mystery | B270: Default | C270: 23.15 | D270: 2 | E270: Yes | F270: 15 | G270: d6670dfe3e7b42bd | H270: 0 | I270: https://books.toscrape.com/catalogue/the-emerald-mystery_842/index.html | J270: https://books.toscrape.com/media/cache/81/58/81586cd0bf8743e1f5ed80b6a0e1fabe.jpg | K270: Three young adults are invited to spend a weekend at the exotic Timber Island. Maria is a professional in the sport of bodyboarding. Tina is an apprentice of the sport but very athletic, and she possesses other skills. And lastly there is Axell, a traveler and a veteran bodyboarder. For them, this invitation is extremely attractive because very few people have visited the Three young adults are invited to spend a weekend at the exotic Timber Island. Maria is a professional in the sport of bodyboarding. Tina is an apprentice of the sport but very athletic, and she possesses other skills. And lastly there is Axell, a traveler and a veteran bodyboarder. For them, this invitation is extremely attractive because very few people have visited the place, also known for its secret surf breaks. The adventure sounds irresistible, so they accept the challenge.Once all the guests are on the island, there is only one thing that worries Luis, their host and fellow bodyboarder: to venture out to find a stretch of secret coastline where the young man says they will face majestic wave no one has ever ridden.By this time all of the guests have encountered some very strange things ... and some question whether they are being watched by someone. But who may want to follow them to an island inhabited by only two people, and for what reason? Are these young riders prepared to solve this mystery and accept what they discover as they investigate? Luckily, you'll also be there to accompany them on their journey and reach your own conclusions in this exciting adventure. ...more
A271: The Fault in Our Stars | B271: Default | C271: 47.22 | D271: 1 | E271: Yes | F271: 5 | G271: 3661360c99719414 | H271: 0 | I271: https://books.toscrape.com/catalogue/the-fault-in-our-stars_403/index.html | J271: https://books.toscrape.com/media/cache/69/61/696100859e82b2ec7a796129d6cca44a.jpg | K271: Despite the tumor-shrinking medical miracle that has bought her a few years, Hazel has never been anything but terminal, her final chapter inscribed upon diagnosis. But when a gorgeous plot twist named Augustus Waters suddenly appears at Cancer Kid Support Group, Hazel's story is about to be completely rewritten.Insightful, bold, irreverent, and raw, The Fault in Our Stars Despite the tumor-shrinking medical miracle that has bought her a few years, Hazel has never been anything but terminal, her final chapter inscribed upon diagnosis. But when a gorgeous plot twist named Augustus Waters suddenly appears at Cancer Kid Support Group, Hazel's story is about to be completely rewritten.Insightful, bold, irreverent, and raw, The Fault in Our Stars is award-winning author John Green's most ambitious and heartbreaking work yet, brilliantly exploring the funny, thrilling, and tragic business of being alive and in love. ...more
A272: The Fellowship of the Ring (The Lord of the Rings #1) | B272: Default | C272: 10.27 | D272: 2 | E272: Yes | F272: 6 | G272: cb17945cb90b7837 | H272: 0 | I272: https://books.toscrape.com/catalogue/the-fellowship-of-the-ring-the-lord-of-the-rings-1_442/index.html | J272: https://books.toscrape.com/media/cache/ed/75/ed75000b92734d99b76a17954857327c.jpg | K272: Frodo Baggins knew the Ringwraiths were searching for him—and the Ring of Power he bore that would enable Sauron to destroy all that was good in Middle-earth. Now it was up to Frodo and his faithful servant Sam to carry the Ring to where it could be destroyed—in the very center of Sauron's dark kingdom.
A273: The Flowers Lied | B273: Default | C273: 16.68 | D273: 2 | E273: Yes | F273: 9 | G273: 33396269bcce166f | H273: 0 | I273: https://books.toscrape.com/catalogue/the-flowers-lied_573/index.html | J273: https://books.toscrape.com/media/cache/a9/f0/a9f00f8505431e64db0f91df762a6d73.jpg | K273: Remember back when you first wanted to become a rock critic? Or when you first started to read music reviews? Those are the days of The Flowers Lied, Michael Goldberg's new rock ‘n’ roll coming-of-age novel. Writerman, the narrator, is a rock critic wannabe obsessed with music – favorites include Captain Beefheart, the Blue Oyster Cult, the 13th Floor Elevators, John Coltr Remember back when you first wanted to become a rock critic? Or when you first started to read music reviews? Those are the days of The Flowers Lied, Michael Goldberg's new rock ‘n’ roll coming-of-age novel. Writerman, the narrator, is a rock critic wannabe obsessed with music – favorites include Captain Beefheart, the Blue Oyster Cult, the 13th Floor Elevators, John Coltrane, Pearls Before Swine, Slim Harpo, Neil Young, Sam Rivers and, of course, Bob Dylan. This novel is for anyone who grew up in the ‘60s or '70s—or anyone who wondered what it was really like to be a teenager back then.Witness Writerman fighting his record buying addition at Odyssey Records as store owner Lucky Larry guzzles Green Death and applies the “upsell," attending a Neil Young concert in 1973 and confronting Neil backstage, pursuing the Visions of Johanna chick of his dreams and ending up naked at the top of a Ferris wheel, alone with his best friend’s girl. ...more
A274: The Girl Who Played with Fire (Millennium Trilogy #2) | B274: Default | C274: 22.14 | D274: 2 | E274: Yes | F274: 3 | G274: bfa9cb304075d3e8 | H274: 0 | I274: https://books.toscrape.com/catalogue/the-girl-who-played-with-fire-millennium-trilogy-2_249/index.html | J274: https://books.toscrape.com/media/cache/11/71/117145e4525b2e801e2cd1ba4dd70441.jpg | K274: Mikael Blomkvist, crusading journalist and publisher of the magazine Millennium, has decided to run a story that will expose an extensive sex trafficking operation between Eastern Europe and Sweden, implicating well-known and highly placed members of Swedish society, business, and government.But he has no idea just how explosive the story will be until, on the eve of publi Mikael Blomkvist, crusading journalist and publisher of the magazine Millennium, has decided to run a story that will expose an extensive sex trafficking operation between Eastern Europe and Sweden, implicating well-known and highly placed members of Swedish society, business, and government.But he has no idea just how explosive the story will be until, on the eve of publication, the two investigating reporters are murdered. And even more shocking for Blomkvist: the fingerprints found on the murder weapon belong to Lisbeth Salander—the troubled, wise-beyond-her-years genius hacker who came to his aid in The Girl with the Dragon Tattoo, and who now becomes the focus and fierce heart of The Girl Who Played with Fire.As Blomkvist, alone in his belief in Salander’s innocence, plunges into an investigation of the slayings, Salander herself is drawn into a murderous hunt in which she is the prey, and which compels her to revisit her dark past in an effort to settle with it once and for all. ...more
A275: The Girl on the Train | B275: Default | C275: 55.02 | D275: 2 | E275: Yes | F275: 15 | G275: e956d67c9bcc5809 | H275: 0 | I275: https://books.toscrape.com/catalogue/the-girl-on-the-train_844/index.html | J275: https://books.toscrape.com/media/cache/25/6c/256c946dd0962095f66c6de3b15ab300.jpg | K275: The debut psychological thriller that will forever change the way you look at other people's lives.EVERY DAY THE SAMERachel takes the same commuter train every morning and night. Every day she rattles down the track, flashes past a stretch of cozy suburban homes, and stops at the signal that allows her to daily watch the same couple breakfasting on their deck. She’s even s The debut psychological thriller that will forever change the way you look at other people's lives.EVERY DAY THE SAMERachel takes the same commuter train every morning and night. Every day she rattles down the track, flashes past a stretch of cozy suburban homes, and stops at the signal that allows her to daily watch the same couple breakfasting on their deck. She’s even started to feel like she knows them. Jess and Jason, she calls them. Their life—as she sees it—is perfect. Not unlike the life she recently lost.UNTIL TODAYAnd then she sees something shocking. It’s only a minute until the train moves on, but it’s enough. Now everything’s changed. Unable to keep it to herself, Rachel goes to the police. But is she really as unreliable as they say? Soon she is deeply entangled not only in the investigation but in the lives of everyone involved. Has she done more harm than good? ...more
A276: The Giver (The Giver Quartet #1) | B276: Default | C276: 12.3 | D276: 1 | E276: Yes | F276: 3 | G276: e2dac1f4739e0bd5 | H276: 0 | I276: https://books.toscrape.com/catalogue/the-giver-the-giver-quartet-1_251/index.html | J276: https://books.toscrape.com/media/cache/b3/ed/b3eda9490c9e2ed02c3a8650e687731b.jpg | K276: Featuring photographic artwork from the feature film on the cover, this handsome edition of The Giver is perfect for fans of the movie and the literary classic. Lois Lowry's 1994 Newbery Medal–winning tale has become one of the most influential novels of our time. The haunting story centers on Jonas who lives in a seemingly ideal, if colorless, world of conformity and cont Featuring photographic artwork from the feature film on the cover, this handsome edition of The Giver is perfect for fans of the movie and the literary classic. Lois Lowry's 1994 Newbery Medal–winning tale has become one of the most influential novels of our time. The haunting story centers on Jonas who lives in a seemingly ideal, if colorless, world of conformity and contentment. Not until he is given his life assignment as the Receiver of Memory does he begin to understand the dark, complex secrets behind his fragile community. Lois Lowry has written three companion novels to The Giver, including Gathering Blue, Messenger, and Son. ...more
A277: The Goldfinch | B277: Default | C277: 43.58 | D277: 3 | E277: Yes | F277: 3 | G277: c88422d8959260ab | H277: 0 | I277: https://books.toscrape.com/catalogue/the-goldfinch_252/index.html | J277: https://books.toscrape.com/media/cache/fb/4d/fb4dde3351d00ef104f29aeecd2d41fb.jpg | K277: It begins with a boy. Theo Decker, a thirteen-year-old New Yorker, miraculously survives an accident that kills his mother. Abandoned by his father, Theo is taken in by the family of a wealthy friend. Bewildered by his strange new home on Park Avenue, disturbed by schoolmates who don't know how to talk to him, and tormented above all by his unbearable longing for his mothe It begins with a boy. Theo Decker, a thirteen-year-old New Yorker, miraculously survives an accident that kills his mother. Abandoned by his father, Theo is taken in by the family of a wealthy friend. Bewildered by his strange new home on Park Avenue, disturbed by schoolmates who don't know how to talk to him, and tormented above all by his unbearable longing for his mother, he clings to one thing that reminds him of her: a small, mysteriously captivating painting that ultimately draws Theo into the underworld of art.As an adult, Theo moves silkily between the drawing rooms of the rich and the dusty labyrinth of an antiques store where he works. He is alienated and in love-and at the center of a narrowing, ever more dangerous circle.The Goldfinch combines vivid characters, mesmerizing language, and suspense, while plumbing with a philosopher's calm the deepest mysteries of love, identity, and art. It is an old-fashioned story of loss and obsession, survival and self-invention, and the ruthless machinations of fate. ...more
...

Sheet Summary
A1: Category | B1: Books | C1: Avg price | D1: Min price | E1: Max price | F1: Avg rating
A2: Default | B2: =COUNTIF(Books!$B$2:$B$1001,A2) | C2: =AVERAGEIF(Books!$B$2:$B$1001,A2,Books!$C$2:$C$1001) | D2: =_xlfn.MINIFS(Books!$C$2:$C$1001,Books!$B$2:$B$1001,A2) | E2: =_xlfn.MAXIFS(Books!$C$2:$C$1001,Books!$B$2:$B$1001,A2) | F2: =AVERAGEIF(Books!$B$2:$B$1001,A2,Books!$D$2:$D$1001)
A3: Nonfiction | B3: =COUNTIF(Books!$B$2:$B$1001,A3) | C3: =AVERAGEIF(Books!$B$2:$B$1001,A3,Books!$C$2:$C$1001) | D3: =_xlfn.MINIFS(Books!$C$2:$C$1001,Books!$B$2:$B$1001,A3) | E3: =_xlfn.MAXIFS(Books!$C$2:$C$1001,Books!$B$2:$B$1001,A3) | F3: =AVERAGEIF(Books!$B$2:$B$1001,A3,Books!$D$2:$D$1001)
A4: Sequential Art | B4: =COUNTIF(Books!$B$2:$B$1001,A4) | C4: =AVERAGEIF(Books!$B$2:$B$1001,A4,Books!$C$2:$C$1001) | D4: =_xlfn.MINIFS(Books!$C$2:$C$1001,Books!$B$2:$B$1001,A4) | E4: =_xlfn.MAXIFS(Books!$C$2:$C$1001,Books!$B$2:$B$1001,A4) | F4: =AVERAGEIF(Books!$B$2:$B$1001,A4,Books!$D$2:$D$1001)
A5: Add a comment | B5: =COUNTIF(Books!$B$2:$B$1001,A5) | C5: =AVERAGEIF(Books!$B$2:$B$1001,A5,Books!$C$2:$C$1001) | D5: =_xlfn.MINIFS(Books!$C$2:$C$1001,Books!$B$2:$B$1001,A5) | E5: =_xlfn.MAXIFS(Books!$C$2:$C$1001,Books!$B$2:$B$1001,A5) | F5: =AVERAGEIF(Books!$B$2:$B$1001,A5,Books!$D$2:$D$1001)
A6: Fiction | B6: =COUNTIF(Books!$B$2:$B$1001,A6) | C6: =AVERAGEIF(Books!$B$2:$B$1001,A6,Books!$C$2:$C$1001) | D6: =_xlfn.MINIFS(Books!$C$2:$C$1001,Books!$B$2:$B$1001,A6) | E6: =_xlfn.MAXIFS(Books!$C$2:$C$1001,Books!$B$2:$B$1001,A6) | F6: =AVERAGEIF(Books!$B$2:$B$1001,A6,Books!$D$2:$D$1001)
A7: Young Adult | B7: =COUNTIF(Books!$B$2:$B$1001,A7) | C7: =AVERAGEIF(Books!$B$2:$B$1001,A7,Books!$C$2:$C$1001) | D7: =_xlfn.MINIFS(Books!$C$2:$C$1001,Books!$B$2:$B$1001,A7) | E7: =_xlfn.MAXIFS(Books!$C$2:$C$1001,Books!$B$2:$B$1001,A7) | F7: =AVERAGEIF(Books!$B$2:$B$1001,A7,Books!$D$2:$D$1001)
A8: Fantasy | B8: =COUNTIF(Books!$B$2:$B$1001,A8) | C8: =AVERAGEIF(Books!$B$2:$B$1001,A8,Books!$C$2:$C$1001) | D8: =_xlfn.MINIFS(Books!$C$2:$C$1001,Books!$B$2:$B$1001,A8) | E8: =_xlfn.MAXIFS(Books!$C$2:$C$1001,Books!$B$2:$B$1001,A8) | F8: =AVERAGEIF(Books!$B$2:$B$1001,A8,Books!$D$2:$D$1001)
